Workbook

Sheet old
A1: номер запроса | B1: время получения | C1: канал запроса | D1: вложения | E1: дата изменения статуса | F1: назначенный агент | G1: время первого ответа | H1: дата первого ответа | I1: время выполнения | J1: выполнен первым ответом | K1: Количество ответов агента | L1: Количество ответов клиента | M1: Флоу
A2: 181442871 | B2: 45383.014 | C2: Telegram | D2: 2 | E2: 45383.519 | F2: Агент 1 | G2: 0.0009837963 | H2: 45383.015 | I2: 0.0035763889 | J2: Да | K2: 1 | L2: 5 | M2: Другие_баги
A3: 181444620 | B3: 45383.04 | C3: Telegram | D3: 1 | E3: 45383.545 | F3: Агент 1 | G3: 0.00060185185 | H3: 45383.041 | I3: 0.00096064815 | J3: Нет | K3: 2 | L3: 3 | M3: Отмена_студентом
A4: 181455692 | B4: 45383.242 | C4: WhatsApp | D4: 0 | E4: 45383.844 | F4: Агент 1 | G4: 0.00052083333 | H4: 45383.243 | I4: 0.094988426 | J4: Нет | K4: 3 | L4: 3 | M4: Отмена_преподавателем
A5: 181457280 | B5: 45383.265 | C5: Telegram | D5: 3 | E5: 45400.161 | F5: Агент 2 | G5: 0.00075231481 | H5: 45383.266 | I5: 14.718252 | J5: Нет | K5: 26 | L5: 37 | M5: Не_пришёл_опоздал_преподаватель
A6: 181458663 | B6: 45383.285 | C6: Email | D6: 0 | E6: 45383.794 | F6: Агент 1 | G6: Нет ответа | H6: Нет ответа | I6: 0.0034375 | J6: Нет | K6: 0 | L6: 1 | M6: Увольнение
A7: 181459476 | B7: 45383.295 | C7: Telegram | D7: 1 | E7: 45383.869 | F7: Агент 1 | G7: 0.00050925926 | H7: 45383.296 | I7: 0.070694444 | J7: Нет | K7: 11 | L7: 17 | M7: Проблема_соединения
A8: 181459541 | B8: 45383.296 | C8: WhatsApp | D8: 0 | E8: 45383.802 | F8: Агент 1 | G8: 0.0016203704 | H8: 45383.298 | I8: 0.0031944444 | J8: Да | K8: 1 | L8: 2 | M8: Проблема_соединения
A9: 181460126 | B9: 45383.301 | C9: Telegram | D9: 0 | E9: 45383.927 | F9: Агент 3 | G9: 0.0017939815 | H9: 45383.303 | I9: 0.12068287 | J9: Нет | K9: 2 | L9: 3 | M9: Технические_уточнения
A10: 181460973 | B10: 45383.311 | C10: WhatsApp | D10: 1 | E10: 45383.82 | F10: Агент 1 | G10: 0.0017361111 | H10: 45383.313 | I10: 0.0021412037 | J10: Да | K10: 1 | L10: 3 | M10: Треш
A11: 181460975 | B11: 45383.311 | C11: Email | D11: 1 | E11: 45383.82 | F11: Агент 1 | G11: 0.0025462963 | H11: 45383.314 | I11: 0.0025578704 | J11: Да | K11: 1 | L11: 1 | M11: Треш
A12: 181460981 | B12: 45383.311 | C12: Telegram | D12: 0 | E12: 45385.276 | F12: Агент 3 | G12: 0.0062731481 | H12: 45383.318 | I12: 1.4625231 | J12: Нет | K12: 3 | L12: 5 | M12: Рефанд
A13: 181461464 | B13: 45383.315 | C13: Telegram | D13: 0 | E13: 45383.82 | F13: Агент 1 | G13: 0.00041666667 | H13: 45383.316 | I13: 0.0013425926 | J13: Нет | K13: 2 | L13: 2 | M13: Отмена_преподавателем
A14: 181462284 | B14: 45383.323 | C14: WhatsApp | D14: 1 | E14: 45383.869 | F14: Агент 1 | G14: 0.0011921296 | H14: 45383.324 | I14: 0.039398148 | J14: Нет | K14: 6 | L14: 7 | M14: Проблема_соединения
A15: 181462776 | B15: 45383.328 | C15: Telegram | D15: 0 | E15: 45383.408 | F15: Агент 4 | G15: 0 | H15: =B15 -> 45383.328 | I15: 0.080011574 | J15: Да | K15: 1 | L15: 1 | M15: Пауза_студент
A16: 181462830 | B16: 45383.328 | C16: Telegram | D16: 1 | E16: 45383.836 | F16: Агент 1 | G16: 0.000625 | H16: 45383.329 | I16: 0.0042592593 | J16: Нет | K16: 5 | L16: 9 | M16: Проблема_соединения
A17: 181463571 | B17: 45383.334 | C17: Telegram | D17: 0 | E17: 45383.844 | F17: Агент 1 | G17: 0.0015972222 | H17: 45383.336 | I17: 0.0024768519 | J17: Нет | K17: 2 | L17: 2 | M17: Вопрос_отзыв_про_студента
A18: 181465358 | B18: 45383.346 | C18: Telegram | D18: 2 | E18: 45383.877 | F18: Агент 4 | G18: 0.0011458333 | H18: 45383.347 | I18: 0.023217593 | J18: Нет | K18: 8 | L18: 10 | M18: Отмена_преподавателем
A19: 181465605 | B19: 45383.347 | C19: Telegram | D19: 3 | E19: 45383.86 | F19: Агент 1 | G19: 0.00064814815 | H19: 45383.348 | I19: 0.0063541667 | J19: Нет | K19: 4 | L19: 6 | M19: Проблема_соединения
A20: 181465922 | B20: 45383.35 | C20: Telegram | D20: 1 | E20: 45383.86 | F20: Агент 4 | G20: 0.0013078704 | H20: 45383.353 | I20: 0.0058796296 | J20: Нет | K20: 2 | L20: 4 | M20: Селфстади
A21: 181466346 | B21: 45383.353 | C21: Telegram | D21: 0 | E21: 45383.86 | F21: Агент 1 | G21: 0.00099537037 | H21: 45383.354 | I21: 0.0018055556 | J21: Да | K21: 1 | L21: 1 | M21: Авторизация_Стафф
A22: 181466354 | B22: 45383.353 | C22: WhatsApp | D22: 0 | E22: 45383.86 | F22: Агент 4 | G22: 0.0022800926 | H22: 45383.355 | I22: 0.0064814815 | J22: Да | K22: 1 | L22: 1 | M22: Вопросы_про_расписание
A23: 181467195 | B23: 45383.358 | C23: WhatsApp | D23: 0 | E23: 45383.47 | F23: Агент 5 | G23: 0.0011111111 | H23: 45383.359 | I23: 0.11163194 | J23: Нет | K23: 3 | L23: 4 | M23: Проблема_оплаты
A24: 181467627 | B24: 45383.361 | C24: Telegram | D24: 2 | E24: 45383.877 | F24: Агент 4 | G24: 0.00068287037 | H24: 45383.362 | I24: 0.012395833 | J24: Нет | K24: 3 | L24: 5 | M24: Механики_тренажёра
A25: 181468047 | B25: 45383.364 | C25: Telegram | D25: 0 | E25: 45383.869 | F25: Агент 1 | G25: 0.00096064815 | H25: 45383.365 | I25: 0.002025463 | J25: Нет | K25: 2 | L25: 2 | M25: Отмена_студентом
A26: 181468909 | B26: 45383.369 | C26: Telegram | D26: 0 | E26: 45383.373 | F26: Агент 4 | G26: 0.0006712963 | H26: 45383.37 | I26: 0.0039467593 | J26: Нет | K26: 2 | L26: 2 | M26: Отмена_преподавателем
A27: 181469358 | B27: 45383.371 | C27: Telegram | D27: 0 | E27: 45383.877 | F27: Агент 1 | G27: 0.0015277778 | H27: 45383.373 | I27: 0.0017939815 | J27: Да | K27: 1 | L27: 1 | M27: Словарь_повторение
... A39: 181475474 | B39: 45383.398 | C39: Telegram | D39: 0 | E39: 45383.448 | F39: Агент 4 | G39: 0.0022222222 | H39: 45383.4 | I39: 0.050752315 | J39: Нет | K39: 3 | L39: 3 | M39: Отмена_преподавателем
A40: 181475879 | B40: 45383.399 | C40: Email | D40: 1 | E40: 45383.935 | F40: Агент 5 | G40: 2.3148148e-05 | H40: 45383.399 | I40: 0.029849537 | J40: Да | K40: 1 | L40: 1
A41: 181476058 | B41: 45383.4 | C41: Email | D41: 0 | E41: 45383.902 | F41: Агент 4 | G41: Нет ответа | H41: Нет ответа | I41: 0.0003587963 | J41: Нет | K41: 0 | L41: 1
A42: 181477246 | B42: 45383.405 | C42: Telegram | D42: 0 | E42: 45383.927 | F42: Агент 5 | G42: 0.0019791667 | H42: 45383.408 | I42: 0.019456019 | J42: Нет | K42: 3 | L42: 6 | M42: Рефанд
A43: 181478219 | B43: 45383.409 | C43: Email | D43: 0 | E43: 45383.409 | F43: Агент 4 | G43: Нет ответа | H43: Нет ответа | I43: 8.1018519e-05 | J43: Нет | K43: 0 | L43: 1
A44: 181478880 | B44: 45383.412 | C44: Telegram | D44: 0 | E44: 45383.43 | F44: Агент 5 | G44: 0.0015625 | H44: 45383.414 | I44: 0.018078704 | J44: Нет | K44: 2 | L44: 3 | M44: Проблема_соединения
A45: 181478942 | B45: 45383.412 | C45: WhatsApp | D45: 0 | E45: 45383.927 | F45: Агент 4 | G45: 0.001724537 | H45: 45383.414 | I45: 0.010763889 | J45: Нет | K45: 2 | L45: 2 | M45: Перенос_аккаунта_или_покупки
A46: 181479987 | B46: 45383.417 | C46: WhatsApp | D46: 0 | E46: 45383.544 | F46: Агент 5 | G46: 0.0016435185 | H46: 45383.419 | I46: 0.12738426 | J46: Нет | K46: 5 | L46: 4 | M46: Перенос_преподавателем
A47: 181480145 | B47: 45383.417 | C47: Telegram | D47: 1 | E47: 45383.935 | F47: Агент 5 | G47: 0.00054398148 | H47: 45383.418 | I47: 0.012916667 | J47: Нет | K47: 2 | L47: 5 | M47: Отмена_студентом
A48: 181480248 | B48: 45383.417 | C48: Telegram | D48: 0 | E48: 45383.927 | F48: Агент 4 | G48: 0.00079861111 | H48: 45383.418 | I48: 0.003125 | J48: Нет | K48: 3 | L48: 3 | M48: Отмена_студентом
A49: 181480404 | B49: 45383.418 | C49: WhatsApp | D49: 0 | E49: 45383.496 | F49: Агент 5 | G49: 0.0019675926 | H49: 45383.42 | I49: 0.07806713 | J49: Нет | K49: 3 | L49: 3 | M49: Отмена_студентом
A50: 181480723 | B50: 45383.419 | C50: WhatsApp | D50: 0 | E50: 45383.927 | F50: Агент 3 | G50: 0.00032407407 | H50: 45383.419 | I50: 0.0029976852 | J50: Нет | K50: 2 | L50: 2 | M50: Изменение_постоянного_расписания
A51: 181480760 | B51: 45383.419 | C51: Telegram | D51: 0 | E51: 45383.509 | F51: Агент 5 | G51: 0.00059027778 | H51: 45383.42 | I51: 0.090115741 | J51: Нет | K51: 7 | L51: 6 | M51: Проблема_оплаты
...

Sheet new
A1: номер запроса | B1: время получения | C1: канал запроса | D1: вложения | E1: дата изменения статуса | F1: назначенный агент | G1: время первого ответа | H1: дата первого ответа | I1: время выполнения | J1: выполнен первым ответом | K1: Количество ответов агента | L1: Количество ответов клиента | M1: Флоу
A2: 185967307 | B2: 45413.001 | C2: WhatsApp | D2: 0 | E2: 45413.511 | F2: Агент 1 | G2: 0.00094907407 | H2: 45413.002 | I2: 0.0040277778 | J2: Нет | K2: 3 | L2: 4 | M2: Перенос_студентом
A3: 185967717 | B3: 45413.005 | C3: Telegram | D3: 0 | E3: 45413.561 | F3: Агент 1 | G3: 0 | H3: =B3 -> 45413.005 | I3: 0.053310185 | J3: Нет | K3: 2 | L3: 1 | M3: Перенос_студентом
A4: 185969797 | B4: 45413.033 | C4: Telegram | D4: 0 | E4: 45413.544 | F4: Агент 1 | G4: 0.006412037 | H4: 45413.04 | I4: 0.0078587963 | J4: Нет | K4: 3 | L4: 2 | M4: История_занятий_преподавателя
A5: 185970380 | B5: 45413.044 | C5: Telegram | D5: 0 | E5: 45413.552 | F5: Агент 1 | G5: 0.00034722222 | H5: 45413.044 | I5: 0.0018402778 | J5: Нет | K5: 3 | L5: 3 | M5: Отмена_преподавателем
A6: 185971899 | B6: 45413.073 | C6: Email | D6: 0 | E6: 45413.577 | F6: Агент 1 | G6: Нет ответа | H6: Нет ответа | I6: 0.00091435185 | J6: Нет | K6: 0 | L6: 1 | M6: Отмена_преподавателем
A7: 185973796 | B7: 45413.117 | C7: WhatsApp | D7: 1 | E7: 45413.619 | F7: Агент 1 | G7: 0.00060185185 | H7: 45413.117 | I7: 0.00078703704 | J7: Да | K7: 1 | L7: 1 | M7: Отмена_студентом
A8: 185975392 | B8: 45413.151 | C8: Email | D8: 0 | E8: 45413.652 | F8: Агент 1 | G8: Нет ответа | H8: Нет ответа | I8: 0.0010069444 | J8: Нет | K8: 0 | L8: 1 | M8: Пауза_преподаватель
A9: 185978794 | B9: 45413.236 | C9: Email | D9: 0 | E9: 45413.744 | F9: Агент 1 | G9: Нет ответа | H9: Нет ответа | I9: 0.00082175926 | J9: Нет | K9: 0 | L9: 1 | M9: Пауза_преподаватель
A10: 185979356 | B10: 45413.25 | C10: Email | D10: 0 | E10: 45413.752 | F10: Агент 1 | G10: Нет ответа | H10: Нет ответа | I10: 0.0013310185 | J10: Нет | K10: 0 | L10: 1 | M10: Отмена_преподавателем
A11: 185981275 | B11: 45413.287 | C11: Telegram | D11: 1 | E11: 45413.794 | F11: Агент 1 | G11: 0.00061342593 | H11: 45413.288 | I11: 0.0027430556 | J11: Нет | K11: 3 | L11: 3 | M11: Селфстади
A12: 185981330 | B12: 45413.288 | C12: WhatsApp | D12: 6 | E12: 45413.819 | F12: Агент 1 | G12: 0.0018171296 | H12: 45413.29 | I12: 0.025972222 | J12: Нет | K12: 7 | L12: 14 | M12: Проблема_соединения
A13: 185981628 | B13: 45413.293 | C13: Telegram | D13: 1 | E13: 45413.802 | F13: Агент 1 | G13: 0 | H13: =B13 -> 45413.293 | I13: 0.0050925926 | J13: Нет | K13: 2 | L13: 3 | M13: Проблема_соединения
A14: 185981923 | B14: 45413.298 | C14: Telegram | D14: 1 | E14: 45413.927 | F14: Агент 6 | G14: 0.00059027778 | H14: 45413.298 | I14: 0.12138889 | J14: Нет | K14: 6 | L14: 9 | M14: Не_пришёл_опоздал_преподаватель
A15: 185982105 | B15: 45413.301 | C15: Telegram | D15: 0 | E15: 45413.802 | F15: Агент 1 | G15: 0 | H15: =B15 -> 45413.301 | I15: 0.00021990741 | J15: Да | K15: 1 | L15: 0 | M15: Не_пришёл_опоздал_преподаватель
A16: 185982112 | B16: 45413.301 | C16: WhatsApp | D16: 1 | E16: 45413.819 | F16: Агент 1 | G16: 0.0006712963 | H16: 45413.302 | I16: 0.010659722 | J16: Нет | K16: 3 | L16: 5 | M16: Не_пришёл_опоздал_студент
A17: 185982142 | B17: 45413.302 | C17: Telegram | D17: 0 | E17: 45414.302 | F17: Агент 6 | G17: 0.00019675926 | H17: 45413.302 | I17: 0.49305556 | J17: Нет | K17: 4 | L17: 5 | M17: Отмена_преподавателем
A18: 185982174 | B18: 45413.302 | C18: Telegram | D18: 0 | E18: 45413.811 | F18: Агент 1 | G18: 0.0040972222 | H18: 45413.306 | I18: 0.0045601852 | J18: Да | K18: 1 | L18: 1 | M18: Отмена_преподавателем
A19: 185982205 | B19: 45413.302 | C19: Email | D19: 0 | E19: 45413.819 | F19: Агент 1 | G19: Нет ответа | H19: Нет ответа | I19: 0.010509259 | J19: Нет | K19: 0 | L19: 1 | M19: Отмена_преподавателем
A20: 185982378 | B20: 45413.305 | C20: Telegram | D20: 0 | E20: 45413.811 | F20: Агент 1 | G20: 0 | H20: =B20 -> 45413.305 | I20: 0.0002662037 | J20: Да | K20: 1 | L20: 0 | M20: Отмена_преподавателем
A21: 185983769 | B21: 45413.326 | C21: Telegram | D21: 0 | E21: 45413.836 | F21: Агент 1 | G21: 0.00040509259 | H21: 45413.326 | I21: 0.0042476852 | J21: Нет | K21: 2 | L21: 2 | M21: Перенос_преподавателем
A22: 185984165 | B22: 45413.331 | C22: Email | D22: 0 | E22: 45413.836 | F22: Агент 1 | G22: Нет ответа | H22: Нет ответа | I22: 0.00082175926 | J22: Нет | K22: 0 | L22: 1 | M22: Пауза_преподаватель
A23: 185984772 | B23: 45413.336 | C23: Telegram | D23: 2 | E23: 45413.852 | F23: Агент 6 | G23: 0.0015393519 | H23: 45413.339 | I23: 0.013900463 | J23: Нет | K23: 4 | L23: 5 | M23: Пауза_студент
A24: 185984953 | B24: 45413.339 | C24: Telegram | D24: 0 | E24: 45413.96 | F24: Агент 7 | G24: 0.00041666667 | H24: 45413.339 | I24: 0.12033565 | J24: Нет | K24: 2 | L24: 2 | M24: Проблема_соединения
A25: 185985501 | B25: 45413.344 | C25: Telegram | D25: 0 | E25: 45413.861 | F25: Агент 6 | G25: 0.0009375 | H25: 45413.345 | I25: 0.0094675926 | J25: Нет | K25: 4 | L25: 5 | M25: Не_пришёл_опоздал_студент
A26: 185987171 | B26: 45413.362 | C26: WhatsApp | D26: 0 | E26: 45414.185 | F26: Агент 6 | G26: 0.0016782407 | H26: 45413.363 | I26: 0.3175463 | J26: Нет | K26: 5 | L26: 8 | M26: Отмена_студентом
A27: 185987424 | B27: 45413.364 | C27: Telegram | D27: 0 | E27: 45413.902 | F27: Агент 6 | G27: 0.0032175926 | H27: 45413.369 | I27: 0.030185185 | J27: Нет | K27: 9 | L27: 13 | M27: Назначить_занятия
A28: 185988457 | B28: 45413.375 | C28: Telegram | D28: 0 | E28: 45413.894 | F28: Агент 6 | G28: 0.00056712963 | H28: 45413.376 | I28: 0.010844907 | J28: Нет | K28: 3 | L28: 3 | M28: История_занятий_преподавателя
A29: 185989595 | B29: 45413.381 | C29: Telegram | D29: 3 | E29: 45413.993 | F29: Агент 7 | G29: 0.0010185185 | H29: 45413.382 | I29: 0.10440972 | J29: Нет | K29: 5 | L29: 9 | M29: Уведомления_смс
A30: 185989600 | B30: 45413.381 | C30: Telegram | D30: 2 | E30: 45414.201 | F30: Агент 6 | G30: 0.0029050926 | H30: 45413.384 | I30: 0.31684028 | J30: Нет | K30: 7 | L30: 15 | M30: История_занятий_преподавателя
A31: 185989993 | B31: 45413.385 | C31: Telegram | D31: 0 | E31: 45413.894 | F31: Агент 7 | G31: 0.00032407407 | H31: 45413.385 | I31: 0.0088425926 | J31: Нет | K31: 6 | L31: 7 | M31: Отмена_преподавателем
A32: 185990090 | B32: 45413.385 | C32: WhatsApp | D32: 2 | E32: 45413.902 | F32: Агент 6 | G32: 0.00042824074 | H32: 45413.386 | I32: 0.0092361111 | J32: Нет | K32: 8 | L32: 11 | M32: Пауза_студент
A33: 185990495 | B33: 45413.387 | C33: Telegram | D33: 1 | E33: 45415.252 | F33: Агент 6 | G33: 0.00099537037 | H33: 45413.388 | I33: 1.3618287 | J33: Нет | K33: 14 | L33: 23 | M33: Вопросы_отзывы_о_преподавателях
A34: 185991984 | B34: 45413.398 | C34: Telegram | D34: 0 | E34: 45413.911 | F34: Агент 6 | G34: 0.0040046296 | H34: 45413.402 | I34: 0.0064467593 | J34: Нет | K34: 2 | L34: 2 | M34: Перенос_преподавателем
... A52: 186004886 | B52: 45413.473 | C52: WhatsApp | D52: 0 | E52: 45413.985 | F52: Агент 8 | G52: 0.00015046296 | H52: 45413.473 | I52: 0.0037847222 | J52: Да | K52: 1 | L52: 1 | M52: Старт
A53: 186004921 | B53: 45413.474 | C53: Telegram | D53: 0 | E53: 45413.985 | F53: Агент 7 | G53: 0 | H53: =B53 -> 45413.474 | I53: 0.010532407 | J53: Нет | K53: 3 | L53: 4 | M53: Не_пришёл_опоздал_преподаватель
A54: 186006257 | B54: 45413.481 | C54: WhatsApp | D54: 0 | E54: 45414.06 | F54: Агент 6 | G54: 0.0011921296 | H54: 45413.482 | I54: 0.073946759 | J54: Нет | K54: 3 | L54: 3 | M54: Пауза_студент
A55: 186006937 | B55: 45413.485 | C55: Telegram | D55: 0 | E55: 45418.936 | F55: Агент 7 | G55: 0.0013310185 | H55: 45413.487 | I55: 4.1078241 | J55: Нет | K55: 3 | L55: 2 | M55: Выплаты_преподавателям
A56: 186006941 | B56: 45413.485 | C56: WhatsApp | D56: 0 | E56: 45414.027 | F56: Агент 8 | G56: 0.00041666667 | H56: 45413.486 | I56: 0.034039352 | J56: Нет | K56: 3 | L56: 2 | M56: Вопросы_отзывы_о_преподавателях
A57: 186008291 | B57: 45413.493 | C57: WhatsApp | D57: 0 | E57: 45415.135 | F57: Агент 8 | G57: 0.0022800926 | H57: 45413.495 | I57: 1.1339005 | J57: Нет | K57: 3 | L57: 10 | M57: Доступы_ресурсы
...

Sheet Общее сравнение
B2: Сравниваемые периоды: | E2: Общее количество | F2: Медианное время ответа | G2: Медианное время решения
B3: Предыдущий | C3: 01.04.2024 - 30.04.2024 | E3: =COUNT(old!A2:A5309) -> 5308 | F3: =MEDIAN(old!G2:G5309) -> 0.0010532407 | G3: =MEDIAN(old!$I$2:$I$5309) -> 0.0079108796
B4: Текущий | C4: 01.05.2024 - 31.05.2024 | E4: =COUNT(new!A2:A4824) -> 4823 | F4: =MEDIAN(new!G2:G4824) -> 0.0011805556 | G4: =MEDIAN(new!$I$2:$I$5309) -> 0.0077083333
B24: По сравнению с прошлым периодом разница составила -9,13% | H24: По сравнению с прошлым периодом разница составила 9,90% | N24: По сравнению с прошлым периодом разница составила -2,63%

Sheet Сравнение по каналам
B2: Распределение запросов по каналам | H2: Медианное время ответа по каналам
B4: Каналы | C4: 01.04.2024 - 30.04.2024 | D4: 01.05.2024 - 31.05.2024 | E4: % изменения | H4: Каналы | I4: 01.04.2024 - 30.04.2024 | J4: 01.05.2024 - 31.05.2024 | K4: % изменения
B5: Email | C5: =COUNTIF(old!$C$2:'old'!$C$5309, $B$5) -> 748 | D5: =COUNTIF(new!$C$2:'new'!$C$5309, B5) -> 645 | E5: -0.1377 | H5: Email | I5: 0.0026851852 | J5: =IFERROR(__xludf.DUMMYFUNCTION("MEDIAN(FILTER(new!$G$3:$G$5310, new!$C$3:$C$5310 = $H5))"),0.00424189814814814) -> 0.0042418981 | K5: =(J5-I5)/I5 -> 0.57974138
B6: Telegram | C6: =COUNTIF(old!$C$2:'old'!$C$5309, $B$6) -> 3610 | D6: =COUNTIF(new!$C$2:'new'!$C$5309, B6) -> 3308 | E6: -0.0837 | H6: Telegram | I6: =IFERROR(__xludf.DUMMYFUNCTION("MEDIAN(FILTER(old!$G$3:$G$5310, old!$C$3:$C$5310 = $H$6))"),0.00103009259259259) -> 0.0010300926 | J6: =IFERROR(__xludf.DUMMYFUNCTION("MEDIAN(FILTER(new!$G$3:$G$5310, new!$C$3:$C$5310 = $H$6))"),0.0011574074074074) -> 0.0011574074 | K6: =(J6-I6)/I6 -> 0.12359551
B7: VK | C7: =COUNTIF(old!$C$2:'old'!$C$5309, $B$7) -> 16 | D7: =COUNTIF(new!$C$2:'new'!$C$5309, B7) -> 18 | E7: 0.125 | H7: VK | I7: =IFERROR(__xludf.DUMMYFUNCTION("MEDIAN(FILTER(old!G4:G5311, old!C4:C5311 = H7))"),0.00123842592592592) -> 0.0012384259 | J7: =IFERROR(__xludf.DUMMYFUNCTION("MEDIAN(FILTER(new!$G$3:$G$5310, new!$C$3:$C$5310 = $H7))"),0.000677083333333333) -> 0.00067708333 | K7: =(J7-I7)/I7 -> -0.45327103
B8: WhatsApp | C8: =COUNTIF(old!$C$2:'old'!$C$5309, $B$8) -> 934 | D8: =COUNTIF(new!$C$2:'new'!$C$5309, B8) -> 852 | E8: -0.0878 | H8: WhatsApp | I8: =IFERROR(__xludf.DUMMYFUNCTION("MEDIAN(FILTER(old!G5:G5312, old!C5:C5312 = H8))"),0.00105324074074074) -> 0.0010532407 | J8: =IFERROR(__xludf.DUMMYFUNCTION("MEDIAN(FILTER(new!$G$3:$G$5310, new!$C$3:$C$5310 = $H8))"),0.00116898148148148) -> 0.0011689815 | K8: =(J8-I8)/I8 -> 0.10989011
B9: Итого | C9: =SUM(C5:C8) -> 5308 | D9: =SUM(D5:D8) -> 4823 | E9: -0.0914
G33: ы
